Workbook

Sheet Dashboard
A1: Dashboard
A2: Walton Hi-Tech Industry
B3: Year: | C3: 2023 | D3: <—*Please select the Year By clicking here
L8: Financial Health | Q8: Efficiency
L10: Selected Year: | N10: =C3 -> 2023 | Q10: Selected Year: | S10: =C3 -> 2023
L11: Indicators | N11: Performance | Q11: Indicators | S11: Performance
L12: Current Ratio | N12: =Calc!K9 -> 1.96 | Q12: =Calc!G17 -> Asset Turnover | S12: =Calc!K17 -> 0.43453375
L13: Acid Ratio | N13: =Calc!K10 -> 1.24 | Q13: =Calc!G18 -> Inventory Turnover | S13: =Calc!K18 -> 1.3929763
L14: Cash Ratio | N14: =Calc!K11 -> 0.07 | Q14: =Calc!G19 -> Inventory Days | S14: =Calc!K19 -> 262.02887
L15: Debt ratio | N15: =Calc!K12 -> 0.21 | Q15: =Calc!G20 -> Receivable Turnover | S15: =Calc!K20 -> 1.7337084
L16: Interest Coverage. | N16: =Calc!K13 -> 2.1 | Q16: =Calc!G21 -> Receivable Days | S16: =Calc!K21 -> 210.53136
L17: Operating CF Margin | N17: =Calc!K15 -> 0.51044096 | Q17: =Calc!G22 -> Payable Days | S17: =Calc!K22 -> 32.406079
L19: Key Financial Insights
L20: Growth | N20: Revenue rose to 13.18% in 2024 before falling to 5.72% in 2025.
L21: Profitability | N21: Profitability fell with net margin lowering to 14.64%. From 18% in 2024
L22: Liquidity | N22: Liquidity improved as current ratio increased from 1.96X to 2.55x
L23: Solvency | N23: Financial leverage declined with DTE falling from 0.3x to 0.22
L24: Effeciency | N24: Asset turnover improved slightly from 0.43x to 0.45x
L25: Cash Flow | N25: Operating Cash flow remained positive at 17.63B.

Sheet Key_P_I
A1: Category | B1: Particulars | C1: 2025 | D1: 2024 | E1: 2023
A2: Performance | B2: Revenue | C2: 70822475704 | D2: 75121154616 | E2: 66374271405
A3: Performance | B3: Net Profit | C3: 10366160364 | D3: 13565259328 | E3: 7826780005
A4: Growth | B4: Revenue growth | C4: -0.057223281 | D4: 0.13178123 | E4: -0.18740322
A5: Growth | B5: Gross Profit Growth | C5: -0.10880819 | D5: 0.22681859 | E5: -0.11997283
A6: Growth | B6: Operating Profit Growth | C6: -0.2115091 | D6: 0.20737601 | E6: -0.10269786
A7: Growth | B7: Net Profit Growth | C7: -0.23583028 | D7: 0.73318521 | E7: -0.35667572
A8: Growth | B8: Asset Growth | C8: 0.0023106389 | D8: 0.077515733 | E8: -0.085344855
A9: Growth | B9: Equity Growth | C9: 0.053891405 | D9: 0.10350145 | E9: 0.0270243
A10: Growth | B10: Operating Cash Flow Growth | C10: 0.021699656 | D10: -0.49067374 | E10: 15.141979
B11: Ratios
A12: Profitability | B12: Gross profit Margin | C12: 0.36049004 | D12: 0.38135631 | E12: 0.35181397
A13: Profitability | B13: Operating Profit Margin | C13: 0.20927373 | D13: 0.2502228 | E13: 0.23455615
A14: Profitability | B14: Net Profit margin | C14: 0.14636823 | D14: 0.18057842 | E14: 0.11791888
A15: Profitability | B15: Return on Asset | C15: 0.065844542 | D15: 0.089483036 | E15: 0.051239735
A16: Profitability | B16: Return on Equity | C16: 0.087850878 | D16: 0.12386935 | E16: 0.076169913
A18: Liquidity | B18: Current Ratio | C18: 2.5500822 | D18: 2.2279701 | E18: 1.96352
A19: Liquidity | B19: Acid Ratio | C19: 1.5133754 | D19: 1.4870534 | E19: 1.2413324
A20: Liquidity | B20: Cash ratio | C20: 0.17712029 | D20: 0.18527616 | E20: 0.068261793
A22: Solvency | B22: Debt to equity Ratio | C22: 0.21849052 | D22: 0.25710392 | E22: 0.29711007
A23: Solvency | B23: Debt ratio | C23: 0.16786253 | D23: 0.18786088 | E23: 0.21198041
A24: Solvency | B24: Interest Coverage | C24: 3.4295496 | D24: 4.1108011 | E24: 2.096988
A26: Effeciency Ratio | B26: Asset Turnover | C26: 0.44985542 | D26: 0.49553561 | E26: 0.43453375
... A38: Cash flow analysis | B38: CFO/Net profit | C38: 0.24893932 | D38: 0.22970957 | E38: 0.51044096

Sheet Profit or loss
A1: Particulars | B1: 01 July 2024 to 30 June 2025 | C1: 01 July 2023 to 30 June 2024 | D1: 01 July 2022 to 30 June 2023 | E1: 01 July 2021 to 30 June 2022
A2: Revenue Net | B2: 70822475704 | C2: 75121154616 | D2: 66374271405 | E2: 81681681284
A3: Cost of Goods Sold | B3: -45291678432 | C3: -46473228347 | D3: -43022875679 | E3: -55146823463
A4: Gross Profit | B4: 25530797272 | C4: 28647926270 | D4: 23351395726 | E4: 26534857822
A5: Operating Expenses
A6: Administrative Expenses | B6: -1695126401 | C6: -1557382355 | D6: -1373610844 | E6: -1389331369
A7: Selling & Distribution Expenses | B7: -9014387103 | C7: -8293518089 | D7: -6409291118 | E7: -7795190297
A8: Total Operating Expenses | B8: -10709513504 | C8: -9850900444 | D8: -7782901962 | E8: -9184521666
A9: Operating Profit | B9: 14821283768 | C9: 18797025826 | D9: 15568493763 | E9: 17350336155
A10: Finance Income | B10: 290334678 | C10: 171221879 | D10: 32175844 | E10: 79765294
A11: Finance Costs | B11: -4484038732 | C11: -4591235836 | D11: -7535855991 | E11: -4738325106
A12: Net Finance Costs | B12: -4193704054 | C12: -4420013957 | D12: -7503680148 | E12: -4658559812
A13: Profit after Finance Costs | B13: 10627579713 | C13: 14377011869 | D13: 8064813616 | E13: 12691776343
A14: Non-Operating Income / (Expenses) | B14: 266614954 | C14: -94590252 | D14: 201930120 | E14: 270571805
A15: Profit before WPPF & Tax | B15: 10894194667 | C15: 14282421617 | D15: 8266743736 | E15: 12962348148
A16: Contribution to WPPF | B16: -518771175 | C16: -680115315 | D16: -393654464 | E16: -617254674
A17: Profit before Tax | B17: 10375423492 | C17: 13602306302 | D17: 7873089272 | E17: 12345093474
A18: Income Tax Expense
A19: Current Tax (Expense) / Income | B19: -10227195 | C19: -57026659 | D19: -47752505 | E19: -65269058
A20: Deferred Tax (Expense) / Income Net | B20: 964067 | C20: 19979685 | D20: 1443239 | E20: -113673860
A21: Total Income Tax Expense | B21: -9263129 | C21: -37046974 | D21: -46309267 | E21: -178942917
A22: Profit / (Loss) after Tax | B22: 10366160364 | C22: 13565259328 | D22: 7826780005 | E22: 12166150557
A23: Other Comprehensive Income
A24: Gain on revaluation of property plant and equipment | B24: 4115909157 | C24: 0 | D24: 31274333219 | E24: 0
A25: Related Tax | B25: -1055547108 | C25: 0 | D25: -514663564 | E25: 0
A26: Other Comprehensive Income net of Tax | B26: 3060362049 | C26: 0 | D26: 30759669655 | E26: 0
A27: Total Comprehensive Income | B27: 13426522413 | C27: 13565259328 | D27: 38586449660 | E27: 12166150557
A28: Earnings Per Share (EPS) | B28: 34.22 | C28: 44.78 | D28: 25.84 | E28: 40.16
A29: EBIT | B29: =B15-B11 -> 15378233399 | C29: =C15-C11 -> 18873657453 | D29: =D15-D11 -> 15802599727 | E29: =E15-E11 -> 17700673254

Sheet Financial Statement
A1: Particulars | B1: 30 June 2025 Amount in Taka | C1: 30 June 2024 Amount in Taka | D1: 30 June 2023 | E1: 30 June 2022
A2: ASSETS
A3: Non-Current Assets
A4: Property Plant and Equipment | B4: 77180420324 | C4: 70863873952 | D4: 68824874693 | E4: 65475136944
A5: Intangible Assets | B5: 46082639 | C5: 16019226 | D5: 19217454 | E5: 13053850
A6: Other Non-Current Assets | B6: 7247599337 | C6: 7437964575 | D6: 7351736250 | E6: 6446187658
A7: Right of Use Assets | B7: 211722011 | C7: 201866955 | D7: 213136270 | E7: 207685994
A8: Total Non-Current Assets | B8: 84685824311 | C8: 78519724708 | D8: 76408964667 | E8: 72142064446
A9: Current Assets
A10: Inventories | B10: 29648739753 | C10: 26182663525 | D10: 25573533341 | E10: 36197619159
A11: Trade and Other Receivables | B11: 36066239999 | C11: 37246629669 | D11: 34674948386 | E11: 41894178885
A12: Advances Deposits and Prepayments | B12: 1486154474 | C12: 7671704651 | D12: 5517637114 | E12: 5536502855
A13: Investment in Securities | B13: 365800204 | C13: 778283932 | D13: 1033741904 | E13: 1186987977
A14: Short Term investments | B14: 297320659 | C14: 305850540 | D14: 313513014 | E14: 278215010
A15: Cash and Cash Equivalents | B15: 5065456980 | C15: 6547326350 | D15: 2417232161 | E15: 2321365628
A16: Total Current Assets | B16: 72929712069 | C16: 78732458667 | D16: 69530605920 | E16: 87414869514
A17: TOTAL ASSETS | B17: 157615536380 | C17: 157252183375 | D17: 145939570587 | E17: 159556933960
A18: EQUITY AND LIABILITIES
A19: Shareholders' Equity
A20: Share Capital | B20: 3029283430 | C20: 3029283430 | D20: 3029283430 | E20: 3029283430
A21: Share Premium | B21: 931683717 | C21: 931683717 | D21: 931683717 | E21: 931683717
A22: Retained Earnings | B22: 83370439512 | C22: 80209560207 | D22: 69403503630 | E22: 66119942829
A23: Revaluation Reserve | B23: 33761916711 | C23: 30730612160 | D23: 30759669655 | E23: 31303390716
A24: Total Shareholders' Equity | B24: 121093323370 | C24: 114901139514 | D24: 104124140432 | E24: 101384300692
A25: Non-Current Liabilities
A26: Long Term Loan | B26: 5625548221 | C26: 5784668868 | D26: 5144327566 | E26: 2584065883
A27: UNDP Fund | B27: 78824932 | C27: 74068576 | D27: 74329381 | E27: 57116262
A28: Lease Liability | B28: 199469372 | C28: 186957709 | D28: 196120077 | E28: 189487463
A29: Deferred Tax Liabilities Net | B29: 2019404737 | C29: 967146295 | D29: 989450580 | E29: 477683129
A30: Total Non-Current Liabilities | B30: 7923247262 | C30: 7012841448 | D30: 6404227604 | E30: 3308352737
A31: Current Liabilities
A32: Trade and Other Payables | B32: 2403051804 | C32: 3630113554 | D32: 3058009690 | E32: 4581457210
A33: Short Term Loan | B33: 17883976956 | C33: 21243601979 | D33: 24096051506 | E33: 42659073516
A34: Long Term Loan-Current Portion | B34: 2948217565 | C34: 2513262116 | D34: 1695951363 | E34: 1331294074
A35: Lease Liability-Current Portion | B35: 39624404 | C35: 41207819 | D35: 35666642 | E35: 28394840
A36: Unclaimed Dividend | B36: 7481253 | C36: 5752783 | D36: 3778478 | E36: 2840777
A37: Provisions and Accruals | B37: 5316613766 | C37: 7904264162 | D37: 6521744872 | E37: 6261220114
A38: Total Current Liabilities | B38: 28598965748 | C38: 35338202413 | D38: 35411202551 | E38: 54864280531
A39: TOTAL EQUITY AND LIABILITIES | B39: 157615536380 | C39: 157252183375 | D39: 145939570587 | E39: 159556933960
A40: Net Assets Value (NAV) Per Share without Revaluation | B40: 288.29 | C40: 277.86 | D40: 242.18 | E40: 231.34
...

Sheet Cash flow
A1: Particulars | B1: 01 Jul 2024 to 30 June 2025 | C1: 01 Jul 2023 to 30 June 2024 | D1: 01 Jul 2022 to 30 June 2023 | E1: 01 Jul 2021 to 30 June 2022
A2: A. Cash Flows from Operating Activities
A3: Received from Customers | B3: 78507560112 | C3: 77419988481 | D3: 78005422848 | E3: 75328836761
A4: Received from Other Income | B4: -300489166 | C4: 44492106 | D4: 122427285 | E4: 133258190
A5: Total Received | B5: 78207070945 | C5: 77464480588 | D5: 78127850133 | E5: 75462094951
A6: Payment to Suppliers and Others | B6: -45919169501 | C6: -47829102523 | D6: -33633766254 | E6: -66973469260
A7: Payment to Employees | B7: -8321592870 | C7: -7264260790 | D7: -6426803156 | E7: -7113919709
A8: Payment for WPPF | B8: -680115315 | C8: -393654464 | D8: -617254674 | E8: -890258781
A9: Total Payment | B9: -54920877686 | C9: -55487017777 | D9: -40677824083 | E9: -74977647750
A10: Cash Generated from Operating Activities | B10: 23286193259 | C10: 21977462811 | D10: 37450026049 | E10: 484447202
A11: Payment against Tax and VAT | B11: -5655694493 | C11: -4721414355 | D11: -3569879509 | E11: -2880161918
A12: Net Cash Generated from Operating Activities | B12: 17630498766 | C12: 17256048456 | D12: 33880146541 | E12: -2395714716
A13: B. Cash Flows from Investing Activities
A14: Acquisition of Property Plant and Equipment and other Non-Current Assets | B14: -5196559175 | C14: -4800875705 | D14: -6424773522 | E14: -7618780348
A15: Acquisition of Intangible Assets | B15: -37926730 | C15: -3824614 | D15: -11488840 | E15: -3637488
A16: Proceeds from Sale of Property Plant and Equipment | B16: 586024 | C16: 4946368 | D16: 18922211 | E16: 7850469
A17: Encashment/ (Payment) of Short Term Investment Net | B17: 8529881 | C17: 7662474 | D17: -35298004 | E17: 1087334219
A18: Encashment/ (Payment) of Investments in Securities | B18: 433082545 | C18: 18925408 | D18: 135402706 | E18: -151424263
A19: Interest Received from FDR and STD | B19: 303774449 | C19: 154894895 | D19: 30659852 | E19: 95872412
A20: Received from Dividend and Other Investment Income | B20: 57467186 | C20: 34690439 | D20: 50758387 | E20: 111353074
A21: Net Cash Used in Investing Activities | B21: -4431045821 | C21: -4583580736 | D21: -6235817210 | E21: -6471431925
A22: C. Cash Flows from Financing Activities
A23: Received from UNDP | B23: 66854714 | C23: 51639360 | D23: 46944872 | E23: 65722821
A24: Dividend Paid | B24: -7236663155 | C24: -2790584847 | D24: -4572791875 | E24: -5173208575
A25: Unclaimed Dividend Paid | B25: 1728470 | C25: 1974305
A26: Payment Lease Liability (Principal) | B26: -41340652 | C26: -37516806 | D26: -30258351 | E26: -35346059
A27: Payment for Financial Costs and Lease Interest | B27: -4388111473 | C27: -4373088074 | D27: -7353240991 | E27: -4301028941
A28: Long Term Loan-Received/(Repaid) Net | B28: 275834802 | C28: 1457652057 | D28: 2924918972 | E28: -1851111438
A29: Short Term Loan-Received/(Repaid) Net | B29: -3359625021 | C29: -2852449527 | D29: -18564035425 | E29: 18779658803
A30: Net Cash Used in Financing Activities | B30: -14681322315 | C30: -8542373532 | D30: -27548462798 | E30: 7484686612
A31: D. Net Increase/ (Decrease) in Cash and Cash Equivalents (A+B+C) | B31: -1481869370 | C31: 4130094189 | D31: 95866533 | E31: -1382460029
A32: E. Cash and Cash Equivalents at Beginning of the Year | B32: 6547326350 | C32: 2417232161 | D32: 2321365628 | E32: 3703825657
A33: F. Cash and Cash Equivalents at End of the Year (D+E) | B33: 5065456980 | C33: 6547326350 | D33: 2417232161 | E33: 2321365628

Sheet Growth
A1: Growth
A2: Particular | B2: 2025 | C2: 2024 | D2: 2023 | E2: 2022
A3: Revenue growth | B3: =('Profit or loss'!B2-'Profit or loss'!C2)/'Profit or loss'!C2 -> -0.057223281 | C3: =('Profit or loss'!C2-'Profit or loss'!D2)/'Profit or loss'!D2 -> 0.13178123 | D3: =('Profit or loss'!D2-'Profit or loss'!E2)/'Profit or loss'!E2 -> -0.18740322
A4: Gross Profit Growth | B4: =('Profit or loss'!B4-'Profit or loss'!C4)/'Profit or loss'!C4 -> -0.10880819 | C4: =('Profit or loss'!C4-'Profit or loss'!D4)/'Profit or loss'!D4 -> 0.22681859 | D4: =('Profit or loss'!D4-'Profit or loss'!E4)/'Profit or loss'!E4 -> -0.11997283
A5: Operating Profit Growth | B5: =('Profit or loss'!B9-'Profit or loss'!C9)/'Profit or loss'!C9 -> -0.2115091 | C5: =('Profit or loss'!C9-'Profit or loss'!D9)/'Profit or loss'!D9 -> 0.20737601 | D5: =('Profit or loss'!D9-'Profit or loss'!E9)/'Profit or loss'!E9 -> -0.10269786
A6: Net Profit Growth | B6: =('Profit or loss'!B22-'Profit or loss'!C22)/'Profit or loss'!C22 -> -0.23583028 | C6: =('Profit or loss'!C22-'Profit or loss'!D22)/'Profit or loss'!D22 -> 0.73318521 | D6: =('Profit or loss'!D22-'Profit or loss'!E22)/'Profit or loss'!E22 -> -0.35667572
A7: Asset Growth | B7: =('Financial Statement'!B17-'Financial Statement'!C17)/'Financial Statement'!C17 -> 0.0023106389 | C7: =('Financial Statement'!C17-'Financial Statement'!D17)/'Financial Statement'!D17 -> 0.077515733 | D7: =('Financial Statement'!D17-'Financial Statement'!E17)/'Financial Statement'!E17 -> -0.085344855
A8: Equity Growth | B8: =('Financial Statement'!B24-'Financial Statement'!C24)/'Financial Statement'!C24 -> 0.053891405 | C8: =('Financial Statement'!C24-'Financial Statement'!D24)/'Financial Statement'!D24 -> 0.10350145 | D8: =('Financial Statement'!D24-'Financial Statement'!E24)/'Financial Statement'!E24 -> 0.0270243
A9: Operating Cash Flow Growth | B9: =('Cash flow'!B12-'Cash flow'!C12)/'Cash flow'!C12 -> 0.021699656 | C9: =('Cash flow'!C12-'Cash flow'!D12)/'Cash flow'!D12 -> -0.49067374 | D9: =ABS(('Cash flow'!D12-'Cash flow'!E12)/'Cash flow'!E12) -> 15.141979
A10: Ratios
A11: Gross profit Margin | B11: ='Profit or loss'!B4/'Profit or loss'!B2 -> 0.36049004 | C11: ='Profit or loss'!C4/'Profit or loss'!C2 -> 0.38135631 | D11: ='Profit or loss'!D4/'Profit or loss'!D2 -> 0.35181397
A12: Operating Profit Margin | B12: =('Profit or loss'!B9/'Profit or loss'!B2) -> 0.20927373 | C12: =('Profit or loss'!C9/'Profit or loss'!C2) -> 0.2502228 | D12: =('Profit or loss'!D9/'Profit or loss'!D2) -> 0.23455615
A13: Net Profit margin | B13: ='Profit or loss'!B22/'Profit or loss'!B2 -> 0.14636823 | C13: ='Profit or loss'!C22/'Profit or loss'!C2 -> 0.18057842 | D13: ='Profit or loss'!D22/'Profit or loss'!D2 -> 0.11791888
A14: Return on Asset | B14: =('Profit or loss'!B22/AVERAGE('Financial Statement'!B17,'Financial Statement'!C17)) -> 0.065844542 | C14: =('Profit or loss'!C22/AVERAGE('Financial Statement'!C17,'Financial Statement'!D17)) -> 0.089483036 | D14: =('Profit or loss'!D22/AVERAGE('Financial Statement'!D17,'Financial Statement'!E17)) -> 0.051239735
A15: Return on Equity | B15: ='Profit or loss'!B22/AVERAGE('Financial Statement'!B24,'Financial Statement'!C24) -> 0.087850878 | C15: ='Profit or loss'!C22/AVERAGE('Financial Statement'!C24,'Financial Statement'!D24) -> 0.12386935 | D15: ='Profit or loss'!D22/AVERAGE('Financial Statement'!D24,'Financial Statement'!E24) -> 0.076169913
A16: Liquidity
A17: Current Ratio | B17: =('Financial Statement'!B16/'Financial Statement'!B38) -> 2.5500822 | C17: =('Financial Statement'!C16/'Financial Statement'!C38) -> 2.2279701 | D17: =('Financial Statement'!D16/'Financial Statement'!D38) -> 1.96352 | E17: =('Financial Statement'!E16/'Financial Statement'!E38) -> 1.5932929
A18: Acid Ratio | B18: =('Financial Statement'!B16-'Financial Statement'!B10)/'Financial Statement'!B38 -> 1.5133754 | C18: =('Financial Statement'!C16-'Financial Statement'!C10)/'Financial Statement'!C38 -> 1.4870534 | D18: =('Financial Statement'!D16-'Financial Statement'!D10)/'Financial Statement'!D38 -> 1.2413324 | E18: =('Financial Statement'!E16-'Financial Statement'!E10)/'Financial Statement'!E38 -> 0.93352633
A19: Cash ratio | B19: =('Financial Statement'!B15/'Financial Statement'!B38) -> 0.17712029 | C19: =('Financial Statement'!C15/'Financial Statement'!C38) -> 0.18527616 | D19: =('Financial Statement'!D15/'Financial Statement'!D38) -> 0.068261793 | E19: =('Financial Statement'!E15/'Financial Statement'!E38) -> 0.042311056
A20: Solvency
A21: Debt to equity Ratio | B21: ='Financial Statement'!B42/'Financial Statement'!B24 -> 0.21849052 | C21: ='Financial Statement'!C42/'Financial Statement'!C24 -> 0.25710392 | D21: ='Financial Statement'!D42/'Financial Statement'!D24 -> 0.29711007 | E21: ='Financial Statement'!E42/'Financial Statement'!E24 -> 0.45938506
A22: Debt ratio | B22: ='Financial Statement'!B42/'Financial Statement'!B17 -> 0.16786253 | C22: ='Financial Statement'!C42/'Financial Statement'!C17 -> 0.18786088 | D22: ='Financial Statement'!D42/'Financial Statement'!D17 -> 0.21198041 | E22: ='Financial Statement'!E42/'Financial Statement'!E17 -> 0.29189852
A23: Interest Coverage | B23: ='Profit or loss'!B29/ABS('Profit or loss'!B11) -> 3.4295496 | C23: ='Profit or loss'!C29/ABS('Profit or loss'!C11) -> 4.1108011 | D23: ='Profit or loss'!D29/ABS('Profit or loss'!D11) -> 2.096988 | E23: ='Profit or loss'!E29/ABS('Profit or loss'!E11) -> 3.7356393 | F23: note: EBIT=PBT+Finance Cost
A24: Effeciency Ratio
A25: Asset Turnover | B25: =('Profit or loss'!B2/AVERAGE('Financial Statement'!B17,'Financial Statement'!C17)) -> 0.44985542 | C25: =('Profit or loss'!C2/AVERAGE('Financial Statement'!C17,'Financial Statement'!D17)) -> 0.49553561 | D25: =('Profit or loss'!D2/AVERAGE('Financial Statement'!D17,'Financial Statement'!E17)) -> 0.43453375
A26: Inventory Turnover | B26: =ABS('Profit or loss'!B3)/AVERAGE('Financial Statement'!B10,'Financial Statement'!C10) -> 1.6224446 | C26: =ABS('Profit or loss'!C3)/AVERAGE('Financial Statement'!C10,'Financial Statement'!D10) -> 1.7958517 | D26: =ABS('Profit or loss'!D3)/AVERAGE('Financial Statement'!D10,'Financial Statement'!E10) -> 1.3929763
A27: Inventory Days | B27: =365/B26 -> 224.96917 | C27: =365/C26 -> 203.24618 | D27: =365/D26 -> 262.02887
A28: Revievable Turnover | B28: =365/B27 -> 1.6224446 | C28: ='Profit or loss'!C2/AVERAGE('Financial Statement'!C11,'Financial Statement'!D11) -> 2.088974 | D28: ='Profit or loss'!D2/AVERAGE('Financial Statement'!D11,'Financial Statement'!E11) -> 1.7337084
A29: Recievable Days | B29: =365/B28 -> 224.96917 | C29: =365/C28 -> 174.72692 | D29: =365/D28 -> 210.53136
A30: Payable Days | B30: =(AVERAGE('Financial Statement'!B32,'Financial Statement'!C32)/ABS('Profit or loss'!B3))*365 -> 24.310264 | C30: =(AVERAGE('Financial Statement'!C32,'Financial Statement'!D32)/ABS('Profit or loss'!C3))*365 -> 26.264207 | D30: =(AVERAGE('Financial Statement'!D32,'Financial Statement'!E32)/ABS('Profit or loss'!D3))*365 -> 32.406079
A31: Cash flow analysis
A32: Operating Cash Flow | B32: ='Cash flow'!B12 -> 17630498766 | C32: ='Cash flow'!C12 -> 17256048456 | D32: ='Cash flow'!D12 -> 33880146541 | E32: ='Cash flow'!E12 -> -2395714716
A33: Operating cash flow margin | B33: =B32/'Profit or loss'!B2 -> 0.24893932 | C33: =C32/'Profit or loss'!C2 -> 0.22970957 | D33: =D32/'Profit or loss'!D2 -> 0.51044096 | E33: =E32/'Profit or loss'!E2 -> -0.02932989
A34: Free Cash Flow | B34: =B32-ABS('Cash flow'!B14) -> 12433939591 | C34: =C32-ABS('Cash flow'!C14) -> 12455172751 | D34: =D32-ABS('Cash flow'!D14) -> 27455373019 | E34: =E32-ABS('Cash flow'!E14) -> -10014495064
A35: Cash flow from investment Activities | B35: ='Cash flow'!B21 -> -4431045821 | C35: ='Cash flow'!C21 -> -4583580736 | D35: ='Cash flow'!D21 -> -6235817210 | E35: ='Cash flow'!E21 -> -6471431925
A36: Cash flow from Financing Activities | B36: ='Cash flow'!B31 -> -1481869370 | C36: ='Cash flow'!C31 -> 4130094189 | D36: ='Cash flow'!D31 -> 95866533 | E36: ='Cash flow'!E31 -> -1382460029
A37: CFO/Net profit | B37: =Growth!B32/'Profit or loss'!B2 -> 0.24893932 | C37: =Growth!C32/'Profit or loss'!C2 -> 0.22970957 | D37: =Growth!D32/'Profit or loss'!D2 -> 0.51044096 | E37: =Growth!E32/'Profit or loss'!E2 -> -0.02932989

Sheet Calc
A1: Category | B1: Particular | C1: 2025 | D1: 2024 | E1: 2023
B2: Revenue | C2: 70822475704 | D2: 75121154616 | E2: 66374271405
B3: Net Profit | C3: 10366160364 | D3: 13565259328 | E3: 7826780005
A4: Growth | B4: Revenue growth | C4: -0.057223281 | D4: 0.13178123 | E4: -0.18740322
A5: Growth | B5: Gross Profit Growth | C5: -0.10880819 | D5: 0.22681859 | E5: -0.11997283
A6: Growth | B6: Operating Profit Growth | C6: -0.2115091 | D6: 0.20737601 | E6: -0.10269786
A7: Growth | B7: Net Profit Growth | C7: -0.23583028 | D7: 0.73318521 | E7: -0.35667572 | G7: Financial Health
A8: Growth | B8: Asset Growth | C8: 0.0023106389 | D8: 0.077515733 | E8: -0.085344855 | H8: 2025 | I8: 2024 | J8: 2023
A9: Growth | B9: Equity Growth | C9: 0.053891405 | D9: 0.10350145 | E9: 0.0270243 | G9: Current Ratio | H9: 2.55 | I9: 2.23 | J9: 1.96 | K9: =_xlfn.XLOOKUP(Dashboard!$C$3,Calc!$H$8:$J$8,Calc!H9:J9) -> 1.96
A10: Growth | B10: Operating Cash Flow Growth | C10: 0.021699656 | D10: -0.49067374 | E10: 15.141979 | G10: Acid Ratio | H10: 1.51 | I10: 1.49 | J10: 1.24 | K10: =_xlfn.XLOOKUP(Dashboard!$C$3,Calc!$H$8:$J$8,Calc!H10:J10) -> 1.24
B11: Ratios | G11: Cash ratio | H11: 0.18 | I11: 0.19 | J11: 0.07 | K11: =_xlfn.XLOOKUP(Dashboard!$C$3,Calc!$H$8:$J$8,Calc!H11:J11) -> 0.07
A12: Profitability | B12: Gross profit Margin | C12: 0.36049004 | D12: 0.38135631 | E12: 0.35181397 | G12: Debt ratio | H12: 0.17 | I12: 0.19 | J12: 0.21 | K12: =_xlfn.XLOOKUP(Dashboard!$C$3,Calc!$H$8:$J$8,Calc!H12:J12) -> 0.21
A13: Profitability | B13: Operating Profit Margin | C13: 0.20927373 | D13: 0.2502228 | E13: 0.23455615 | G13: Interest Coverage | H13: 3.43 | I13: 4.11 | J13: 2.1 | K13: =_xlfn.XLOOKUP(Dashboard!$C$3,Calc!$H$8:$J$8,Calc!H13:J13) -> 2.1
A14: Profitability | B14: Net Profit margin | C14: 0.14636823 | D14: 0.18057842 | E14: 0.11791888
A15: Profitability | B15: Return on Asset | C15: 0.065844542 | D15: 0.089483036 | E15: 0.051239735 | G15: Operating cash flow margin | H15: 0.24893932 | I15: 0.22970957 | J15: 0.51044096 | K15: =_xlfn.XLOOKUP(Dashboard!$C$3,Calc!$H$8:$J$8,Calc!H15:J15) -> 0.51044096
A16: Profitability | B16: Return on Equity | C16: 0.087850878 | D16: 0.12386935 | E16: 0.076169913 | G16: Effeciency
G17: Asset Turnover | H17: 0.44985542 | I17: 0.49553561 | J17: 0.43453375 | K17: =_xlfn.XLOOKUP(Dashboard!$C$3,Calc!$H$8:$J$8,Calc!H17:J17) -> 0.43453375
A18: Liquidity | B18: Current Ratio | C18: 2.5500822 | D18: 2.2279701 | E18: 1.96352 | G18: Inventory Turnover | H18: 1.6224446 | I18: 1.7958517 | J18: 1.3929763 | K18: =_xlfn.XLOOKUP(Dashboard!$C$3,$C$1:$E$1,C27:E27) -> 1.3929763
A19: Liquidity | B19: Acid Ratio | C19: 1.5133754 | D19: 1.4870534 | E19: 1.2413324 | G19: Inventory Days | H19: 224.96917 | I19: 203.24618 | J19: 262.02887 | K19: =_xlfn.XLOOKUP(Dashboard!$C$3,$C$1:$E$1,C28:E28) -> 262.02887
A20: Liquidity | B20: Cash ratio | C20: 0.17712029 | D20: 0.18527616 | E20: 0.068261793 | G20: Receivable Turnover | H20: 1.6224446 | I20: 2.088974 | J20: 1.7337084 | K20: =_xlfn.XLOOKUP(Dashboard!$C$3,$C$1:$E$1,C29:E29) -> 1.7337084
G21: Receivable Days | H21: 224.96917 | I21: 174.72692 | J21: 210.53136 | K21: =_xlfn.XLOOKUP(Dashboard!$C$3,$C$1:$E$1,C30:E30) -> 210.53136
A22: Solvency | B22: Debt to equity Ratio | C22: 0.21849052 | D22: 0.25710392 | E22: 0.29711007 | G22: Payable Days | H22: 24.310264 | I22: 26.264207 | J22: 32.406079 | K22: =_xlfn.XLOOKUP(Dashboard!$C$3,$C$1:$E$1,C31:E31) -> 32.406079
A23: Solvency | B23: Debt ratio | C23: 0.16786253 | D23: 0.18786088 | E23: 0.21198041
A24: Solvency | B24: Interest Coverage | C24: 3.4295496 | D24: 4.1108011 | E24: 2.096988
A26: Effeciency Ratio | B26: Asset Turnover | C26: 0.44985542 | D26: 0.49553561 | E26: 0.43453375
A27: Effeciency Ratio | B27: Inventory Turnover | C27: 1.6224446 | D27: 1.7958517 | E27: 1.3929763
A28: Effeciency Ratio | B28: Inventory Days | C28: 224.96917 | D28: 203.24618 | E28: 262.02887
A29: Effeciency Ratio | B29: Revievable Turnover | C29: 1.9320612 | D29: 2.088974 | E29: 1.7337084
A30: Effeciency Ratio | B30: Recievable Days | C30: 188.91741 | D30: 174.72692 | E30: 210.53136
A31: Effeciency Ratio | B31: Payable Days | C31: 24.310264 | D31: 26.264207 | E31: 32.406079
A33: Cash flow analysis | B33: Operating Cash Flow | C33: 17630498766 | D33: 17256048456 | E33: 33880146541
A34: Cash flow analysis | B34: Operating cash flow margin | C34: 0.24893932 | D34: 0.22970957 | E34: 0.51044096
A35: Cash flow analysis | B35: Free Cash Flow | C35: 12433939591 | D35: 12455172751 | E35: 27455373019
A36: Cash flow analysis | B36: Cash flow from investment Activities | C36: -4431045821 | D36: -4583580736 | E36: -6235817210
... A38: Cash flow analysis | B38: CFO/Net profit | C38: 0.24893932 | D38: 0.22970957 | E38: 0.51044096

Sheet KPI
A1: >
A2: Category | C2: 2025 | D2: 2024 | E2: 2023
B3: Revenue | C3: ='Profit or loss'!B2 -> 70822475704 | D3: ='Profit or loss'!C2 -> 75121154616 | E3: ='Profit or loss'!D2 -> 66374271405
B4: Net Profit | C4: ='Profit or loss'!B22 -> 10366160364 | D4: ='Profit or loss'!C22 -> 13565259328 | E4: ='Profit or loss'!D22 -> 7826780005
A5: Growth | B5: Revenue growth | C5: =('Profit or loss'!B2-'Profit or loss'!C2)/'Profit or loss'!C2 -> -0.057223281 | D5: =('Profit or loss'!C2-'Profit or loss'!D2)/'Profit or loss'!D2 -> 0.13178123 | E5: =('Profit or loss'!D2-'Profit or loss'!E2)/'Profit or loss'!E2 -> -0.18740322 | G5: CF characterstics | K5: Revenue | L5: =_xlfn.XLOOKUP(Dashboard!$C$3,KPI!$C$2:$E$2,$C$3:$E$3) -> 66374271405
A6: Growth | B6: Gross Profit Growth | C6: =('Profit or loss'!B4-'Profit or loss'!C4)/'Profit or loss'!C4 -> -0.10880819 | D6: =('Profit or loss'!C4-'Profit or loss'!D4)/'Profit or loss'!D4 -> 0.22681859 | E6: =('Profit or loss'!D4-'Profit or loss'!E4)/'Profit or loss'!E4 -> -0.11997283 | H6: 2025 | I6: 2024 | J6: 2023 | K6: net Profit | L6: =_xlfn.XLOOKUP(Dashboard!$C$3,C2:E2,C4:E4) -> 7826780005
A7: Growth | B7: Operating Profit Growth | C7: =('Profit or loss'!B9-'Profit or loss'!C9)/'Profit or loss'!C9 -> -0.2115091 | D7: =('Profit or loss'!C9-'Profit or loss'!D9)/'Profit or loss'!D9 -> 0.20737601 | E7: =('Profit or loss'!D9-'Profit or loss'!E9)/'Profit or loss'!E9 -> -0.10269786 | G7: Operating CF | H7: ='Cash flow'!B12 -> 17630498766 | I7: ='Cash flow'!C12 -> 17256048456 | J7: ='Cash flow'!D12 -> 33880146541 | K7: Net Margin | L7: =_xlfn.XLOOKUP(Dashboard!$C$3,$C$2:$E$2,C15:E15) -> 0.11791888
A8: Growth | B8: Net Profit Growth | C8: =('Profit or loss'!B22-'Profit or loss'!C22)/'Profit or loss'!C22 -> -0.23583028 | D8: =('Profit or loss'!C22-'Profit or loss'!D22)/'Profit or loss'!D22 -> 0.73318521 | E8: =('Profit or loss'!D22-'Profit or loss'!E22)/'Profit or loss'!E22 -> -0.35667572 | G8: Investing CF | H8: ='Cash flow'!B21 -> -4431045821 | I8: ='Cash flow'!C21 -> -4583580736 | J8: ='Cash flow'!D21 -> -6235817210 | K8: ROE | L8: =_xlfn.XLOOKUP(Dashboard!$C$3,$C$2:$E$2,$C$17:$E$17) -> 0.076169913
A9: Growth | B9: Asset Growth | C9: =('Financial Statement'!B17-'Financial Statement'!C17)/'Financial Statement'!C17 -> 0.0023106389 | D9: =('Financial Statement'!C17-'Financial Statement'!D17)/'Financial Statement'!D17 -> 0.077515733 | E9: =('Financial Statement'!D17-'Financial Statement'!E17)/'Financial Statement'!E17 -> -0.085344855 | G9: Financing CF | H9: ='Cash flow'!B30 -> -14681322315 | I9: ='Cash flow'!C30 -> -8542373532 | J9: ='Cash flow'!D30 -> -27548462798 | K9: Operating Cash Flow | L9: =_xlfn.XLOOKUP(Dashboard!$C$3,C2:E2,C34:E34) -> 33880146541
A10: Growth | B10: Equity Growth | C10: =('Financial Statement'!B24-'Financial Statement'!C24)/'Financial Statement'!C24 -> 0.053891405 | D10: =('Financial Statement'!C24-'Financial Statement'!D24)/'Financial Statement'!D24 -> 0.10350145 | E10: =('Financial Statement'!D24-'Financial Statement'!E24)/'Financial Statement'!E24 -> 0.0270243 | K10: Debt to equity | L10: =_xlfn.XLOOKUP(Dashboard!$C$3,$C$2:$E$2,$C$23:$E$23) -> 0.29711007
A11: Growth | B11: Operating Cash Flow Growth | C11: =('Cash flow'!B12-'Cash flow'!C12)/'Cash flow'!C12 -> 0.021699656 | D11: =('Cash flow'!C12-'Cash flow'!D12)/'Cash flow'!D12 -> -0.49067374 | E11: =ABS(('Cash flow'!D12-'Cash flow'!E12)/'Cash flow'!E12) -> 15.141979
B12: Ratios
A13: Profitability | B13: Gross profit Margin | C13: ='Profit or loss'!B4/'Profit or loss'!B2 -> 0.36049004 | D13: ='Profit or loss'!C4/'Profit or loss'!C2 -> 0.38135631 | E13: ='Profit or loss'!D4/'Profit or loss'!D2 -> 0.35181397 | L13: 2023 | M13: 2024 | N13: 2025
A14: Profitability | B14: Operating Profit Margin | C14: =('Profit or loss'!B9/'Profit or loss'!B2) -> 0.20927373 | D14: =('Profit or loss'!C9/'Profit or loss'!C2) -> 0.2502228 | E14: =('Profit or loss'!D9/'Profit or loss'!D2) -> 0.23455615 | K14: Revenue | L14: 66374271405 | M14: 75121154616 | N14: 70822475704
A15: Profitability | B15: Net Profit margin | C15: ='Profit or loss'!B22/'Profit or loss'!B2 -> 0.14636823 | D15: ='Profit or loss'!C22/'Profit or loss'!C2 -> 0.18057842 | E15: ='Profit or loss'!D22/'Profit or loss'!D2 -> 0.11791888 | K15: Net Profit | L15: 7826780005 | M15: 13565259328 | N15: 10366160364
A16: Profitability | B16: Return on Asset | C16: =('Profit or loss'!B22/AVERAGE('Financial Statement'!B17,'Financial Statement'!C17)) -> 0.065844542 | D16: =('Profit or loss'!C22/AVERAGE('Financial Statement'!C17,'Financial Statement'!D17)) -> 0.089483036 | E16: =('Profit or loss'!D22/AVERAGE('Financial Statement'!D17,'Financial Statement'!E17)) -> 0.051239735
A17: Profitability | B17: Return on Equity | C17: ='Profit or loss'!B22/AVERAGE('Financial Statement'!B24,'Financial Statement'!C24) -> 0.087850878 | D17: ='Profit or loss'!C22/AVERAGE('Financial Statement'!C24,'Financial Statement'!D24) -> 0.12386935 | E17: ='Profit or loss'!D22/AVERAGE('Financial Statement'!D24,'Financial Statement'!E24) -> 0.076169913
A19: Liquidity | B19: Current Ratio | C19: =('Financial Statement'!B16/'Financial Statement'!B38) -> 2.5500822 | D19: =('Financial Statement'!C16/'Financial Statement'!C38) -> 2.2279701 | E19: =('Financial Statement'!D16/'Financial Statement'!D38) -> 1.96352
A20: Liquidity | B20: Acid Ratio | C20: =('Financial Statement'!B16-'Financial Statement'!B10)/'Financial Statement'!B38 -> 1.5133754 | D20: =('Financial Statement'!C16-'Financial Statement'!C10)/'Financial Statement'!C38 -> 1.4870534 | E20: =('Financial Statement'!D16-'Financial Statement'!D10)/'Financial Statement'!D38 -> 1.2413324
A21: Liquidity | B21: Cash ratio | C21: =('Financial Statement'!B15/'Financial Statement'!B38) -> 0.17712029 | D21: =('Financial Statement'!C15/'Financial Statement'!C38) -> 0.18527616 | E21: =('Financial Statement'!D15/'Financial Statement'!D38) -> 0.068261793
A23: Solvency | B23: Debt to equity Ratio | C23: ='Financial Statement'!B42/'Financial Statement'!B24 -> 0.21849052 | D23: ='Financial Statement'!C42/'Financial Statement'!C24 -> 0.25710392 | E23: ='Financial Statement'!D42/'Financial Statement'!D24 -> 0.29711007
A24: Solvency | B24: Debt ratio | C24: ='Financial Statement'!B42/'Financial Statement'!B17 -> 0.16786253 | D24: ='Financial Statement'!C42/'Financial Statement'!C17 -> 0.18786088 | E24: ='Financial Statement'!D42/'Financial Statement'!D17 -> 0.21198041
A25: Solvency | B25: Interest Coverage | C25: ='Profit or loss'!B29/ABS('Profit or loss'!B11) -> 3.4295496 | D25: ='Profit or loss'!C29/ABS('Profit or loss'!C11) -> 4.1108011 | E25: ='Profit or loss'!D29/ABS('Profit or loss'!D11) -> 2.096988
A27: Effeciency Ratio | B27: Asset Turnover | C27: =('Profit or loss'!B2/AVERAGE('Financial Statement'!B17,'Financial Statement'!C17)) -> 0.44985542 | D27: =('Profit or loss'!C2/AVERAGE('Financial Statement'!C17,'Financial Statement'!D17)) -> 0.49553561 | E27: =('Profit or loss'!D2/AVERAGE('Financial Statement'!D17,'Financial Statement'!E17)) -> 0.43453375
A28: Effeciency Ratio | B28: Inventory Turnover | C28: =ABS('Profit or loss'!B3)/AVERAGE('Financial Statement'!B10,'Financial Statement'!C10) -> 1.6224446 | D28: =ABS('Profit or loss'!C3)/AVERAGE('Financial Statement'!C10,'Financial Statement'!D10) -> 1.7958517 | E28: =ABS('Profit or loss'!D3)/AVERAGE('Financial Statement'!D10,'Financial Statement'!E10) -> 1.3929763
A29: Effeciency Ratio | B29: Inventory Days | C29: =365/C28 -> 224.96917 | D29: =365/D28 -> 203.24618 | E29: =365/E28 -> 262.02887
A30: Effeciency Ratio | B30: Revievable Turnover | C30: ='Profit or loss'!B2/AVERAGE('Financial Statement'!B11,'Financial Statement'!C11) -> 1.9320612 | D30: ='Profit or loss'!C2/AVERAGE('Financial Statement'!C11,'Financial Statement'!D11) -> 2.088974 | E30: ='Profit or loss'!D2/AVERAGE('Financial Statement'!D11,'Financial Statement'!E11) -> 1.7337084
A31: Effeciency Ratio | B31: Recievable Days | C31: =365/C30 -> 188.91741 | D31: =365/D30 -> 174.72692 | E31: =365/E30 -> 210.53136
A32: Effeciency Ratio | B32: Payable Days | C32: =(AVERAGE('Financial Statement'!B32,'Financial Statement'!C32)/ABS('Profit or loss'!B3))*365 -> 24.310264 | D32: =(AVERAGE('Financial Statement'!C32,'Financial Statement'!D32)/ABS('Profit or loss'!C3))*365 -> 26.264207 | E32: =(AVERAGE('Financial Statement'!D32,'Financial Statement'!E32)/ABS('Profit or loss'!D3))*365 -> 32.406079
A34: Cash flow analysis | B34: Operating Cash Flow | C34: ='Cash flow'!B12 -> 17630498766 | D34: ='Cash flow'!C12 -> 17256048456 | E34: ='Cash flow'!D12 -> 33880146541
A35: Cash flow analysis | B35: Operating cash flow margin | C35: =C34/'Profit or loss'!B2 -> 0.24893932 | D35: =D34/'Profit or loss'!C2 -> 0.22970957 | E35: =E34/'Profit or loss'!D2 -> 0.51044096
A36: Cash flow analysis | B36: Free Cash Flow | C36: =C34-ABS('Cash flow'!B14) -> 12433939591 | D36: =D34-ABS('Cash flow'!C14) -> 12455172751 | E36: =E34-ABS('Cash flow'!D14) -> 27455373019
A37: Cash flow analysis | B37: Cash flow from investment Activities | C37: ='Cash flow'!B21 -> -4431045821 | D37: ='Cash flow'!C21 -> -4583580736 | E37: ='Cash flow'!D21 -> -6235817210
A38: Cash flow analysis | B38: Cash flow from Financing Activities | C38: ='Cash flow'!B31 -> -1481869370 | D38: ='Cash flow'!C31 -> 4130094189 | E38: ='Cash flow'!D31 -> 95866533
A39: Cash flow analysis | B39: CFO/Net profit | C39: =Growth!B32/'Profit or loss'!B2 -> 0.24893932 | D39: =Growth!C32/'Profit or loss'!C2 -> 0.22970957 | E39: =Growth!D32/'Profit or loss'!D2 -> 0.51044096

Sheet Sheet5
A1: Category | D1: Growth | E1: Growth | F1: Growth | G1: Growth | H1: Growth | I1: Growth | J1: Growth | L1: Profitability | M1: Profitability | N1: Profitability | O1: Profitability | P1: Profitability | R1: Liquidity | S1: Liquidity | T1: Liquidity | U1: Solvency | V1: Solvency | W1: Solvency | Y1: Effeciency Ratio | Z1: Effeciency Ratio | AA1: Effeciency Ratio | AB1: Effeciency Ratio | AC1: Effeciency Ratio | AD1: Effeciency Ratio | AF1: Cash flow analysis | AG1: Cash flow analysis | AH1: Cash flow analysis | AI1: Cash flow analysis | AJ1: Cash flow analysis | AK1: Cash flow analysis
A2: Particular | B2: Revenue | C2: Net Profit | D2: Revenue growth | E2: Gross Profit Growth | F2: Operating Profit Growth | G2: Net Profit Growth | H2: Asset Growth | I2: Equity Growth | J2: Operating Cash Flow Growth | K2: Ratios | L2: Gross profit Margin | M2: Operating Profit Margin | N2: Net Profit margin | O2: Return on Asset | P2: Return on Equity | R2: Current Ratio | S2: Acid Ratio | T2: Cash ratio | U2: Debt to equity Ratio | V2: Debt ratio | W2: Interest Coverage | Y2: Asset Turnover | Z2: Inventory Turnover | AA2: Inventory Days | AB2: Revievable Turnover | AC2: Recievable Days | AD2: Payable Days | AF2: Operating Cash Flow | AG2: Operating cash flow margin | AH2: Free Cash Flow | AI2: Cash flow from investment Activities | AJ2: Cash flow from Financing Activities | AK2: CFO/Net profit
A3: 2025 | B3: 70822475704 | C3: 10366160364 | D3: -0.057223281 | E3: -0.10880819 | F3: -0.2115091 | G3: -0.23583028 | H3: 0.0023106389 | I3: 0.053891405 | J3: 0.021699656 | L3: 0.36049004 | M3: 0.20927373 | N3: 0.14636823 | O3: 0.065844542 | P3: 0.087850878 | R3: 2.5500822 | S3: 1.5133754 | T3: 0.17712029 | U3: 0.21849052 | V3: 0.16786253 | W3: 3.4295496 | Y3: 0.44985542 | Z3: 1.6224446 | AA3: 224.96917 | AB3: 1.6224446 | AC3: 224.96917 | AD3: 24.310264 | AF3: 17630498766 | AG3: 0.24893932 | AH3: 12433939591 | AI3: -4431045821 | AJ3: -1481869370 | AK3: 0.24893932
A4: 2024 | B4: 75121154616 | C4: 13565259328 | D4: 0.13178123 | E4: 0.22681859 | F4: 0.20737601 | G4: 0.73318521 | H4: 0.077515733 | I4: 0.10350145 | J4: -0.49067374 | L4: 0.38135631 | M4: 0.2502228 | N4: 0.18057842 | O4: 0.089483036 | P4: 0.12386935 | R4: 2.2279701 | S4: 1.4870534 | T4: 0.18527616 | U4: 0.25710392 | V4: 0.18786088 | W4: 4.1108011 | Y4: 0.49553561 | Z4: 1.7958517 | AA4: 203.24618 | AB4: 2.088974 | AC4: 174.72692 | AD4: 26.264207 | AF4: 17256048456 | AG4: 0.22970957 | AH4: 12455172751 | AI4: -4583580736 | AJ4: 4130094189 | AK4: 0.22970957
A5: 2023 | B5: 66374271405 | C5: 7826780005 | D5: -0.18740322 | E5: -0.11997283 | F5: -0.10269786 | G5: -0.35667572 | H5: -0.085344855 | I5: 0.0270243 | J5: 15.141979 | L5: 0.35181397 | M5: 0.23455615 | N5: 0.11791888 | O5: 0.051239735 | P5: 0.076169913 | R5: 1.96352 | S5: 1.2413324 | T5: 0.068261793 | U5: 0.29711007 | V5: 0.21198041 | W5: 2.096988 | Y5: 0.43453375 | Z5: 1.3929763 | AA5: 262.02887 | AB5: 1.7337084 | AC5: 210.53136 | AD5: 32.406079 | AF5: 33880146541 | AG5: 0.51044096 | AH5: 27455373019 | AI5: -6235817210 | AJ5: 95866533 | AK5: 0.51044096
G10: Gross profit Margin | H10: Operating Profit Margin | I10: Net Profit margin
F11: 2023 | G11: 0.35181397 | H11: 0.23455615 | I11: 0.11791888
F12: 2024 | G12: 0.38135631 | H12: 0.2502228 | I12: 0.18057842
F13: 2025 | G13: 0.36049004 | H13: 0.20927373 | I13: 0.14636823
